Workbook

Sheet 班级课程成绩
A1: 班级课程成绩表
A2: 班级 | B2: 学号 | C2: 离散数学 | D2: 程序设计 | E2: 电子技术应用 | F2: 数据结构 | G2: 操作系统 | H2: 计算机组成原理 | I2: 平均成绩 | J2: 名次
A3: 1班 | B3: 2032601 | C3: 53 | D3: 74 | E3: 45 | F3: 60 | G3: 60 | H3: 29 | I3: =AVERAGE(C3:H3) -> 53.5 | J3: =_xlfn.RANK.EQ(I3,$I$3:$I$40,0) -> 30
A4: 1班 | B4: 2032602 | C4: 90 | D4: 87 | E4: 91 | F4: 92 | G4: 90 | H4: 86 | I4: =AVERAGE(C4:H4) -> 89.333333 | J4: =_xlfn.RANK.EQ(I4,$I$3:$I$40,0) -> 1
A5: 1班 | B5: 2032603 | C5: 63 | D5: 76 | E5: 65 | F5: 63 | G5: 60 | H5: 64 | I5: =AVERAGE(C5:H5) -> 65.166667 | J5: =_xlfn.RANK.EQ(I5,$I$3:$I$40,0) -> 19
A6: 1班 | B6: 2032604 | C6: 60 | D6: 47 | E6: 28 | F6: 60 | G6: 60 | H6: 24 | I6: =AVERAGE(C6:H6) -> 46.5 | J6: =_xlfn.RANK.EQ(I6,$I$3:$I$40,0) -> 33
A7: 1班 | B7: 2032605 | C7: 70 | D7: 71 | E7: 70 | F7: 62 | G7: 60 | H7: 63 | I7: =AVERAGE(C7:H7) -> 66 | J7: =_xlfn.RANK.EQ(I7,$I$3:$I$40,0) -> 17
A8: 1班 | B8: 2032606 | C8: 60 | D8: 80 | E8: 76 | F8: 75 | G8: 60 | H8: 60 | I8: =AVERAGE(C8:H8) -> 68.5 | J8: =_xlfn.RANK.EQ(I8,$I$3:$I$40,0) -> 15
A9: 1班 | B9: 2032607 | C9: 65 | D9: 87 | E9: 77 | F9: 63 | G9: 70 | H9: 70 | I9: =AVERAGE(C9:H9) -> 72 | J9: =_xlfn.RANK.EQ(I9,$I$3:$I$40,0) -> 14
A10: 1班 | B10: 2032608 | C10: 42 | D10: 41 | E10: 38 | F10: 60 | G10: 60 | H10: 2 | I10: =AVERAGE(C10:H10) -> 40.5 | J10: =_xlfn.RANK.EQ(I10,$I$3:$I$40,0) -> 37
A11: 1班 | B11: 2032609 | C11: 75 | D11: 74 | E11: 74 | F11: 68 | G11: 70 | H11: 89 | I11: =AVERAGE(C11:H11) -> 75 | J11: =_xlfn.RANK.EQ(I11,$I$3:$I$40,0) -> 10
A12: 1班 | B12: 2032610 | C12: 90 | D12: 69 | E12: 94 | F12: 53 | G12: 80 | H12: 63 | I12: =AVERAGE(C12:H12) -> 74.833333 | J12: =_xlfn.RANK.EQ(I12,$I$3:$I$40,0) -> 11
A13: 1班 | B13: 2032611 | C13: 89 | D13: 78 | E13: 80 | F13: 71 | G13: 85 | H13: 94 | I13: =AVERAGE(C13:H13) -> 82.833333 | J13: =_xlfn.RANK.EQ(I13,$I$3:$I$40,0) -> 5
A14: 1班 | B14: 2032612 | C14: 71 | D14: 73 | E14: 81 | F14: 61 | G14: 85 | H14: 85 | I14: =AVERAGE(C14:H14) -> 76 | J14: =_xlfn.RANK.EQ(I14,$I$3:$I$40,0) -> 8
... A40: 3班 | B40: 2032638 | C40: 82 | D40: 0 | E40: 77 | F40: 80 | G40: 65 | H40: 84 | I40: =AVERAGE(C40:H40) -> 64.666667 | J40: =_xlfn.RANK.EQ(I40,$I$3:$I$40,0) -> 21

Sheet 班级课程学分
A1: 班级 | B1: 学号 | C1: 离散数学 | D1: 程序设计 | E1: 电子技术应用 | F1: 数据结构 | G1: 操作系统 | H1: 计算机组成原理 | I1: 总学分 | J1: 学期评价
C2: 学分 | D2: 学分 | E2: 学分 | F2: 学分 | G2: 学分 | H2: 学分 | L2: 课程名称 | M2: 对应学分
A3: 1班 | B3: 2032601 | C3: =IF(班级课程成绩!C3>=60,$M$3,0) -> 0 | D3: =IF(班级课程成绩!D3>=60,$M$4,0) -> 3 | E3: =IF(班级课程成绩!E3>=60,$M$5,0) -> 0 | F3: =IF(班级课程成绩!F3>=60,$M$6,0) -> 5 | G3: =IF(班级课程成绩!G3>=60,$M$7,0) -> 2 | H3: =IF(班级课程成绩!H3>=60,$M$8,0) -> 0 | I3: =SUM(C3:H3) -> 10 | J3: =IF(I3>=15,"A",IF(I3>=10,"B","C")) -> B | L3: 离散数学 | M3: =VLOOKUP(L3,课程对应学分!$A$1:$B$23,2,0) -> 4
A4: 1班 | B4: 2032602 | C4: =IF(班级课程成绩!C4>=60,$M$3,0) -> 4 | D4: =IF(班级课程成绩!D4>=60,$M$4,0) -> 3 | E4: =IF(班级课程成绩!E4>=60,$M$5,0) -> 2 | F4: =IF(班级课程成绩!F4>=60,$M$6,0) -> 5 | G4: =IF(班级课程成绩!G4>=60,$M$7,0) -> 2 | H4: =IF(班级课程成绩!H4>=60,$M$8,0) -> 3 | I4: =SUM(C4:H4) -> 19 | J4: =IF(I4>=15,"A",IF(I4>=10,"B","C")) -> A | L4: 程序设计 | M4: =VLOOKUP(L4,课程对应学分!$A$1:$B$23,2,0) -> 3
A5: 1班 | B5: 2032603 | C5: =IF(班级课程成绩!C5>=60,$M$3,0) -> 4 | D5: =IF(班级课程成绩!D5>=60,$M$4,0) -> 3 | E5: =IF(班级课程成绩!E5>=60,$M$5,0) -> 2 | F5: =IF(班级课程成绩!F5>=60,$M$6,0) -> 5 | G5: =IF(班级课程成绩!G5>=60,$M$7,0) -> 2 | H5: =IF(班级课程成绩!H5>=60,$M$8,0) -> 3 | I5: =SUM(C5:H5) -> 19 | J5: =IF(I5>=15,"A",IF(I5>=10,"B","C")) -> A | L5: 电子技术应用 | M5: =VLOOKUP(L5,课程对应学分!$A$1:$B$23,2,0) -> 2
A6: 1班 | B6: 2032604 | C6: =IF(班级课程成绩!C6>=60,$M$3,0) -> 4 | D6: =IF(班级课程成绩!D6>=60,$M$4,0) -> 0 | E6: =IF(班级课程成绩!E6>=60,$M$5,0) -> 0 | F6: =IF(班级课程成绩!F6>=60,$M$6,0) -> 5 | G6: =IF(班级课程成绩!G6>=60,$M$7,0) -> 2 | H6: =IF(班级课程成绩!H6>=60,$M$8,0) -> 0 | I6: =SUM(C6:H6) -> 11 | J6: =IF(I6>=15,"A",IF(I6>=10,"B","C")) -> B | L6: 数据结构 | M6: =VLOOKUP(L6,课程对应学分!$A$1:$B$23,2,0) -> 5
A7: 1班 | B7: 2032605 | C7: =IF(班级课程成绩!C7>=60,$M$3,0) -> 4 | D7: =IF(班级课程成绩!D7>=60,$M$4,0) -> 3 | E7: =IF(班级课程成绩!E7>=60,$M$5,0) -> 2 | F7: =IF(班级课程成绩!F7>=60,$M$6,0) -> 5 | G7: =IF(班级课程成绩!G7>=60,$M$7,0) -> 2 | H7: =IF(班级课程成绩!H7>=60,$M$8,0) -> 3 | I7: =SUM(C7:H7) -> 19 | J7: =IF(I7>=15,"A",IF(I7>=10,"B","C")) -> A | L7: 操作系统 | M7: =VLOOKUP(L7,课程对应学分!$A$1:$B$23,2,0) -> 2
A8: 1班 | B8: 2032606 | C8: =IF(班级课程成绩!C8>=60,$M$3,0) -> 4 | D8: =IF(班级课程成绩!D8>=60,$M$4,0) -> 3 | E8: =IF(班级课程成绩!E8>=60,$M$5,0) -> 2 | F8: =IF(班级课程成绩!F8>=60,$M$6,0) -> 5 | G8: =IF(班级课程成绩!G8>=60,$M$7,0) -> 2 | H8: =IF(班级课程成绩!H8>=60,$M$8,0) -> 3 | I8: =SUM(C8:H8) -> 19 | J8: =IF(I8>=15,"A",IF(I8>=10,"B","C")) -> A | L8: 计算机组成原理 | M8: =VLOOKUP(L8,课程对应学分!$A$1:$B$23,2,0) -> 3
A9: 1班 | B9: 2032607 | C9: =IF(班级课程成绩!C9>=60,$M$3,0) -> 4 | D9: =IF(班级课程成绩!D9>=60,$M$4,0) -> 3 | E9: =IF(班级课程成绩!E9>=60,$M$5,0) -> 2 | F9: =IF(班级课程成绩!F9>=60,$M$6,0) -> 5 | G9: =IF(班级课程成绩!G9>=60,$M$7,0) -> 2 | H9: =IF(班级课程成绩!H9>=60,$M$8,0) -> 3 | I9: =SUM(C9:H9) -> 19 | J9: =IF(I9>=15,"A",IF(I9>=10,"B","C")) -> A
A10: 1班 | B10: 2032608 | C10: =IF(班级课程成绩!C10>=60,$M$3,0) -> 0 | D10: =IF(班级课程成绩!D10>=60,$M$4,0) -> 0 | E10: =IF(班级课程成绩!E10>=60,$M$5,0) -> 0 | F10: =IF(班级课程成绩!F10>=60,$M$6,0) -> 5 | G10: =IF(班级课程成绩!G10>=60,$M$7,0) -> 2 | H10: =IF(班级课程成绩!H10>=60,$M$8,0) -> 0 | I10: =SUM(C10:H10) -> 7 | J10: =IF(I10>=15,"A",IF(I10>=10,"B","C")) -> C
A11: 1班 | B11: 2032609 | C11: =IF(班级课程成绩!C11>=60,$M$3,0) -> 4 | D11: =IF(班级课程成绩!D11>=60,$M$4,0) -> 3 | E11: =IF(班级课程成绩!E11>=60,$M$5,0) -> 2 | F11: =IF(班级课程成绩!F11>=60,$M$6,0) -> 5 | G11: =IF(班级课程成绩!G11>=60,$M$7,0) -> 2 | H11: =IF(班级课程成绩!H11>=60,$M$8,0) -> 3 | I11: =SUM(C11:H11) -> 19 | J11: =IF(I11>=15,"A",IF(I11>=10,"B","C")) -> A | L11: 学期评价对照表
A12: 1班 | B12: 2032610 | C12: =IF(班级课程成绩!C12>=60,$M$3,0) -> 4 | D12: =IF(班级课程成绩!D12>=60,$M$4,0) -> 3 | E12: =IF(班级课程成绩!E12>=60,$M$5,0) -> 2 | F12: =IF(班级课程成绩!F12>=60,$M$6,0) -> 0 | G12: =IF(班级课程成绩!G12>=60,$M$7,0) -> 2 | H12: =IF(班级课程成绩!H12>=60,$M$8,0) -> 3 | I12: =SUM(C12:H12) -> 14 | J12: =IF(I12>=15,"A",IF(I12>=10,"B","C")) -> B | L12: 成绩范围 | M12: 成绩等级
A13: 1班 | B13: 2032611 | C13: =IF(班级课程成绩!C13>=60,$M$3,0) -> 4 | D13: =IF(班级课程成绩!D13>=60,$M$4,0) -> 3 | E13: =IF(班级课程成绩!E13>=60,$M$5,0) -> 2 | F13: =IF(班级课程成绩!F13>=60,$M$6,0) -> 5 | G13: =IF(班级课程成绩!G13>=60,$M$7,0) -> 2 | H13: =IF(班级课程成绩!H13>=60,$M$8,0) -> 3 | I13: =SUM(C13:H13) -> 19 | J13: =IF(I13>=15,"A",IF(I13>=10,"B","C")) -> A | L13: 总学分>=15 | M13: A
A14: 1班 | B14: 2032612 | C14: =IF(班级课程成绩!C14>=60,$M$3,0) -> 4 | D14: =IF(班级课程成绩!D14>=60,$M$4,0) -> 3 | E14: =IF(班级课程成绩!E14>=60,$M$5,0) -> 2 | F14: =IF(班级课程成绩!F14>=60,$M$6,0) -> 5 | G14: =IF(班级课程成绩!G14>=60,$M$7,0) -> 2 | H14: =IF(班级课程成绩!H14>=60,$M$8,0) -> 3 | I14: =SUM(C14:H14) -> 19 | J14: =IF(I14>=15,"A",IF(I14>=10,"B","C")) -> A | L14: 15>总学分>=10 | M14: B
A15: 1班 | B15: 2032613 | C15: =IF(班级课程成绩!C15>=60,$M$3,0) -> 0 | D15: =IF(班级课程成绩!D15>=60,$M$4,0) -> 3 | E15: =IF(班级课程成绩!E15>=60,$M$5,0) -> 0 | F15: =IF(班级课程成绩!F15>=60,$M$6,0) -> 0 | G15: =IF(班级课程成绩!G15>=60,$M$7,0) -> 0 | H15: =IF(班级课程成绩!H15>=60,$M$8,0) -> 0 | I15: =SUM(C15:H15) -> 3 | J15: =IF(I15>=15,"A",IF(I15>=10,"B","C")) -> C | L15: 成绩<10 | M15: C
A16: 2班 | B16: 2032614 | C16: =IF(班级课程成绩!C16>=60,$M$3,0) -> 0 | D16: =IF(班级课程成绩!D16>=60,$M$4,0) -> 3 | E16: =IF(班级课程成绩!E16>=60,$M$5,0) -> 0 | F16: =IF(班级课程成绩!F16>=60,$M$6,0) -> 5 | G16: =IF(班级课程成绩!G16>=60,$M$7,0) -> 0 | H16: =IF(班级课程成绩!H16>=60,$M$8,0) -> 3 | I16: =SUM(C16:H16) -> 11 | J16: =IF(I16>=15,"A",IF(I16>=10,"B","C")) -> B
A17: 2班 | B17: 2032615 | C17: =IF(班级课程成绩!C17>=60,$M$3,0) -> 4 | D17: =IF(班级课程成绩!D17>=60,$M$4,0) -> 3 | E17: =IF(班级课程成绩!E17>=60,$M$5,0) -> 2 | F17: =IF(班级课程成绩!F17>=60,$M$6,0) -> 5 | G17: =IF(班级课程成绩!G17>=60,$M$7,0) -> 2 | H17: =IF(班级课程成绩!H17>=60,$M$8,0) -> 3 | I17: =SUM(C17:H17) -> 19 | J17: =IF(I17>=15,"A",IF(I17>=10,"B","C")) -> A
A18: 2班 | B18: 2032616 | C18: =IF(班级课程成绩!C18>=60,$M$3,0) -> 4 | D18: =IF(班级课程成绩!D18>=60,$M$4,0) -> 3 | E18: =IF(班级课程成绩!E18>=60,$M$5,0) -> 0 | F18: =IF(班级课程成绩!F18>=60,$M$6,0) -> 5 | G18: =IF(班级课程成绩!G18>=60,$M$7,0) -> 2 | H18: =IF(班级课程成绩!H18>=60,$M$8,0) -> 0 | I18: =SUM(C18:H18) -> 14 | J18: =IF(I18>=15,"A",IF(I18>=10,"B","C")) -> B
A19: 2班 | B19: 2032617 | C19: =IF(班级课程成绩!C19>=60,$M$3,0) -> 4 | D19: =IF(班级课程成绩!D19>=60,$M$4,0) -> 3 | E19: =IF(班级课程成绩!E19>=60,$M$5,0) -> 2 | F19: =IF(班级课程成绩!F19>=60,$M$6,0) -> 0 | G19: =IF(班级课程成绩!G19>=60,$M$7,0) -> 2 | H19: =IF(班级课程成绩!H19>=60,$M$8,0) -> 3 | I19: =SUM(C19:H19) -> 14 | J19: =IF(I19>=15,"A",IF(I19>=10,"B","C")) -> B
A20: 2班 | B20: 2032618 | C20: =IF(班级课程成绩!C20>=60,$M$3,0) -> 4 | D20: =IF(班级课程成绩!D20>=60,$M$4,0) -> 3 | E20: =IF(班级课程成绩!E20>=60,$M$5,0) -> 2 | F20: =IF(班级课程成绩!F20>=60,$M$6,0) -> 5 | G20: =IF(班级课程成绩!G20>=60,$M$7,0) -> 2 | H20: =IF(班级课程成绩!H20>=60,$M$8,0) -> 3 | I20: =SUM(C20:H20) -> 19 | J20: =IF(I20>=15,"A",IF(I20>=10,"B","C")) -> A
A21: 2班 | B21: 2032619 | C21: =IF(班级课程成绩!C21>=60,$M$3,0) -> 4 | D21: =IF(班级课程成绩!D21>=60,$M$4,0) -> 3 | E21: =IF(班级课程成绩!E21>=60,$M$5,0) -> 2 | F21: =IF(班级课程成绩!F21>=60,$M$6,0) -> 5 | G21: =IF(班级课程成绩!G21>=60,$M$7,0) -> 2 | H21: =IF(班级课程成绩!H21>=60,$M$8,0) -> 3 | I21: =SUM(C21:H21) -> 19 | J21: =IF(I21>=15,"A",IF(I21>=10,"B","C")) -> A
A22: 2班 | B22: 2032620 | C22: =IF(班级课程成绩!C22>=60,$M$3,0) -> 4 | D22: =IF(班级课程成绩!D22>=60,$M$4,0) -> 3 | E22: =IF(班级课程成绩!E22>=60,$M$5,0) -> 2 | F22: =IF(班级课程成绩!F22>=60,$M$6,0) -> 5 | G22: =IF(班级课程成绩!G22>=60,$M$7,0) -> 2 | H22: =IF(班级课程成绩!H22>=60,$M$8,0) -> 3 | I22: =SUM(C22:H22) -> 19 | J22: =IF(I22>=15,"A",IF(I22>=10,"B","C")) -> A
A23: 2班 | B23: 2032621 | C23: =IF(班级课程成绩!C23>=60,$M$3,0) -> 4 | D23: =IF(班级课程成绩!D23>=60,$M$4,0) -> 3 | E23: =IF(班级课程成绩!E23>=60,$M$5,0) -> 2 | F23: =IF(班级课程成绩!F23>=60,$M$6,0) -> 5 | G23: =IF(班级课程成绩!G23>=60,$M$7,0) -> 2 | H23: =IF(班级课程成绩!H23>=60,$M$8,0) -> 3 | I23: =SUM(C23:H23) -> 19 | J23: =IF(I23>=15,"A",IF(I23>=10,"B","C")) -> A
A24: 2班 | B24: 2032622 | C24: =IF(班级课程成绩!C24>=60,$M$3,0) -> 4 | D24: =IF(班级课程成绩!D24>=60,$M$4,0) -> 3 | E24: =IF(班级课程成绩!E24>=60,$M$5,0) -> 2 | F24: =IF(班级课程成绩!F24>=60,$M$6,0) -> 0 | G24: =IF(班级课程成绩!G24>=60,$M$7,0) -> 2 | H24: =IF(班级课程成绩!H24>=60,$M$8,0) -> 3 | I24: =SUM(C24:H24) -> 14 | J24: =IF(I24>=15,"A",IF(I24>=10,"B","C")) -> B
A25: 2班 | B25: 2032623 | C25: =IF(班级课程成绩!C25>=60,$M$3,0) -> 4 | D25: =IF(班级课程成绩!D25>=60,$M$4,0) -> 3 | E25: =IF(班级课程成绩!E25>=60,$M$5,0) -> 2 | F25: =IF(班级课程成绩!F25>=60,$M$6,0) -> 5 | G25: =IF(班级课程成绩!G25>=60,$M$7,0) -> 2 | H25: =IF(班级课程成绩!H25>=60,$M$8,0) -> 0 | I25: =SUM(C25:H25) -> 16 | J25: =IF(I25>=15,"A",IF(I25>=10,"B","C")) -> A
A26: 2班 | B26: 2032624 | C26: =IF(班级课程成绩!C26>=60,$M$3,0) -> 4 | D26: =IF(班级课程成绩!D26>=60,$M$4,0) -> 3 | E26: =IF(班级课程成绩!E26>=60,$M$5,0) -> 2 | F26: =IF(班级课程成绩!F26>=60,$M$6,0) -> 0 | G26: =IF(班级课程成绩!G26>=60,$M$7,0) -> 2 | H26: =IF(班级课程成绩!H26>=60,$M$8,0) -> 0 | I26: =SUM(C26:H26) -> 11 | J26: =IF(I26>=15,"A",IF(I26>=10,"B","C")) -> B
A27: 2班 | B27: 2032625 | C27: =IF(班级课程成绩!C27>=60,$M$3,0) -> 4 | D27: =IF(班级课程成绩!D27>=60,$M$4,0) -> 3 | E27: =IF(班级课程成绩!E27>=60,$M$5,0) -> 2 | F27: =IF(班级课程成绩!F27>=60,$M$6,0) -> 0 | G27: =IF(班级课程成绩!G27>=60,$M$7,0) -> 2 | H27: =IF(班级课程成绩!H27>=60,$M$8,0) -> 3 | I27: =SUM(C27:H27) -> 14 | J27: =IF(I27>=15,"A",IF(I27>=10,"B","C")) -> B
... A40: 3班 | B40: 2032638 | C40: =IF(班级课程成绩!C40>=60,$M$3,0) -> 4 | D40: =IF(班级课程成绩!D40>=60,$M$4,0) -> 0 | E40: =IF(班级课程成绩!E40>=60,$M$5,0) -> 2 | F40: =IF(班级课程成绩!F40>=60,$M$6,0) -> 5 | G40: =IF(班级课程成绩!G40>=60,$M$7,0) -> 2 | H40: =IF(班级课程成绩!H40>=60,$M$8,0) -> 3 | I40: =SUM(C40:H40) -> 16 | J40: =IF(I40>=15,"A",IF(I40>=10,"B","C")) -> A

Sheet 课程对应学分
A1: 课程名称 | B1: 对应学分
A2: 职业生涯规划 | B2: 2
A3: 编译原理 | B3: 1
A4: 离散数学 | B4: 4
A5: 计算机系统结构 | B5: 2
A6: 数据分析 | B6: 3
A7: 数据库应用开发 | B7: 4
A8: 计算机组成原理 | B8: 3
A9: 办公软件应用 | B9: 5
A10: 软件测试技术 | B10: 2
A11: 电子技术应用 | B11: 2
A12: 分布式数据库 | B12: 4
A13: 微机系统 | B13: 1
... A23: 移动计算 | B23: 5

Sheet 班级成绩
A1: 班级课程成绩表
A2: 班级 | B2: 学号 | C2: 离散数学 | D2: 程序设计 | E2: 电子技术应用 | F2: 数据结构 | G2: 操作系统 | H2: 计算机组成原理 | I2: 平均成绩 | J2: 名次
A3: 1班 | B3: 2032602 | C3: 90 | D3: 87 | E3: 91 | F3: 92 | G3: 90 | H3: 86 | I3: =AVERAGE(C3:H3) -> 89.333333 | J3: =_xlfn.RANK.EQ(I3,$I$3:$I$42,0) -> 3
A4: 1班 | B4: 2032611 | C4: 89 | D4: 78 | E4: 80 | F4: 71 | G4: 85 | H4: 94 | I4: =AVERAGE(C4:H4) -> 82.833333 | J4: =_xlfn.RANK.EQ(I4,$I$3:$I$42,0) -> 7
A5: 1班 | B5: 2032612 | C5: 71 | D5: 73 | E5: 81 | F5: 61 | G5: 85 | H5: 85 | I5: =AVERAGE(C5:H5) -> 76 | J5: =_xlfn.RANK.EQ(I5,$I$3:$I$42,0) -> 10
A6: 1班 | B6: 2032609 | C6: 75 | D6: 74 | E6: 74 | F6: 68 | G6: 70 | H6: 89 | I6: =AVERAGE(C6:H6) -> 75 | J6: =_xlfn.RANK.EQ(I6,$I$3:$I$42,0) -> 12
A7: 1班 | B7: 2032610 | C7: 90 | D7: 69 | E7: 94 | F7: 53 | G7: 80 | H7: 63 | I7: =AVERAGE(C7:H7) -> 74.833333 | J7: =_xlfn.RANK.EQ(I7,$I$3:$I$42,0) -> 13
A8: 1班 | B8: 2032607 | C8: 65 | D8: 87 | E8: 77 | F8: 63 | G8: 70 | H8: 70 | I8: =AVERAGE(C8:H8) -> 72 | J8: =_xlfn.RANK.EQ(I8,$I$3:$I$42,0) -> 16
A9: 1班 | B9: 2032606 | C9: 60 | D9: 80 | E9: 76 | F9: 75 | G9: 60 | H9: 60 | I9: =AVERAGE(C9:H9) -> 68.5 | J9: =_xlfn.RANK.EQ(I9,$I$3:$I$42,0) -> 17
A10: 1班 | B10: 2032605 | C10: 70 | D10: 71 | E10: 70 | F10: 62 | G10: 60 | H10: 63 | I10: =AVERAGE(C10:H10) -> 66 | J10: =_xlfn.RANK.EQ(I10,$I$3:$I$42,0) -> 19
A11: 1班 | B11: 2032603 | C11: 63 | D11: 76 | E11: 65 | F11: 63 | G11: 60 | H11: 64 | I11: =AVERAGE(C11:H11) -> 65.166667 | J11: =_xlfn.RANK.EQ(I11,$I$3:$I$42,0) -> 21
A12: 1班 | B12: 2032601 | C12: 53 | D12: 74 | E12: 45 | F12: 60 | G12: 60 | H12: 29 | I12: =AVERAGE(C12:H12) -> 53.5 | J12: =_xlfn.RANK.EQ(I12,$I$3:$I$42,0) -> 32
A13: 1班 | B13: 2032604 | C13: 60 | D13: 47 | E13: 28 | F13: 60 | G13: 60 | H13: 24 | I13: =AVERAGE(C13:H13) -> 46.5 | J13: =_xlfn.RANK.EQ(I13,$I$3:$I$42,0) -> 35
A14: 1班 | B14: 2032608 | C14: 42 | D14: 41 | E14: 38 | F14: 60 | G14: 60 | H14: 2 | I14: =AVERAGE(C14:H14) -> 40.5 | J14: =_xlfn.RANK.EQ(I14,$I$3:$I$42,0) -> 39
A15: 1班 | B15: 2032613 | C15: 44 | D15: 67 | E15: 15 | F15: 53 | G15: 30 | H15: 33 | I15: =AVERAGE(C15:H15) -> 40.333333 | J15: =_xlfn.RANK.EQ(I15,$I$3:$I$42,0) -> 40
A16: 1班 汇总 | I16: =SUBTOTAL(9,I3:I15) -> 850.5
A17: 2班 | B17: 2032627 | C17: 97 | D17: 77 | E17: 85 | F17: 76 | G17: 90 | H17: 86 | I17: =AVERAGE(C17:H17) -> 85.166667 | J17: =_xlfn.RANK.EQ(I17,$I$3:$I$42,0) -> 5
A18: 2班 | B18: 2032615 | C18: 93 | D18: 86 | E18: 82 | F18: 76 | G18: 85 | H18: 84 | I18: =AVERAGE(C18:H18) -> 84.333333 | J18: =_xlfn.RANK.EQ(I18,$I$3:$I$42,0) -> 6
A19: 2班 | B19: 2032620 | C19: 86 | D19: 81 | E19: 83 | F19: 75 | G19: 60 | H19: 86 | I19: =AVERAGE(C19:H19) -> 78.5 | J19: =_xlfn.RANK.EQ(I19,$I$3:$I$42,0) -> 8
A20: 2班 | B20: 2032626 | C20: 88 | D20: 86 | E20: 88 | F20: 61 | G20: 65 | H20: 78 | I20: =AVERAGE(C20:H20) -> 77.666667 | J20: =_xlfn.RANK.EQ(I20,$I$3:$I$42,0) -> 9
A21: 2班 | B21: 2032618 | C21: 85 | D21: 77 | E21: 81 | F21: 60 | G21: 60 | H21: 93 | I21: =AVERAGE(C21:H21) -> 76 | J21: =_xlfn.RANK.EQ(I21,$I$3:$I$42,0) -> 10
A22: 2班 | B22: 2032621 | C22: 87 | D22: 73 | E22: 88 | F22: 71 | G22: 60 | H22: 66 | I22: =AVERAGE(C22:H22) -> 74.166667 | J22: =_xlfn.RANK.EQ(I22,$I$3:$I$42,0) -> 14
A23: 2班 | B23: 2032617 | C23: 77 | D23: 81 | E23: 82 | F23: 51 | G23: 60 | H23: 87 | I23: =AVERAGE(C23:H23) -> 73 | J23: =_xlfn.RANK.EQ(I23,$I$3:$I$42,0) -> 15
A24: 2班 | B24: 2032622 | C24: 78 | D24: 83 | E24: 62 | F24: 50 | G24: 60 | H24: 66 | I24: =AVERAGE(C24:H24) -> 66.5 | J24: =_xlfn.RANK.EQ(I24,$I$3:$I$42,0) -> 18
A25: 2班 | B25: 2032625 | C25: 79 | D25: 72 | E25: 60 | F25: 49 | G25: 60 | H25: 72 | I25: =AVERAGE(C25:H25) -> 65.333333 | J25: =_xlfn.RANK.EQ(I25,$I$3:$I$42,0) -> 20
A26: 2班 | B26: 2032619 | C26: 73 | D26: 70 | E26: 60 | F26: 66 | G26: 60 | H26: 61 | I26: =AVERAGE(C26:H26) -> 65 | J26: =_xlfn.RANK.EQ(I26,$I$3:$I$42,0) -> 22
A27: 2班 | B27: 2032623 | C27: 69 | D27: 78 | E27: 73 | F27: 62 | G27: 60 | H27: 23 | I27: =AVERAGE(C27:H27) -> 60.833333 | J27: =_xlfn.RANK.EQ(I27,$I$3:$I$42,0) -> 26
A28: 2班 | B28: 2032628 | C28: 75 | D28: 71 | E28: 30 | F28: 60 | G28: 60 | H28: 62 | I28: =AVERAGE(C28:H28) -> 59.666667 | J28: =_xlfn.RANK.EQ(I28,$I$3:$I$42,0) -> 28
... A31: 2班 | B31: 2032614 | C31: 35 | D31: 64 | E31: 10 | F31: 60 | G31: 30 | H31: 68 | I31: =AVERAGE(C31:H31) -> 44.5 | J31: =_xlfn.RANK.EQ(I31,$I$3:$I$42,0) -> 36
A32: 2班 汇总 | I32: =SUBTOTAL(9,I17:I31) -> 1021
A33: 3班 | B33: 2032633 | C33: 91 | D33: 87 | E33: 86 | F33: 92 | G33: 85 | H33: 88 | I33: =AVERAGE(C33:H33) -> 88.166667 | J33: =_xlfn.RANK.EQ(I33,$I$3:$I$42,0) -> 4
A34: 3班 | B34: 2032634 | C34: 82 | D34: 63 | E34: 69 | F34: 48 | G34: 60 | H34: 66 | I34: =AVERAGE(C34:H34) -> 64.666667 | J34: =_xlfn.RANK.EQ(I34,$I$3:$I$42,0) -> 23
A35: 3班 | B35: 2032638 | C35: 82 | D35: 0 | E35: 77 | F35: 80 | G35: 65 | H35: 84 | I35: =AVERAGE(C35:H35) -> 64.666667 | J35: =_xlfn.RANK.EQ(I35,$I$3:$I$42,0) -> 23
A36: 3班 | B36: 2032632 | C36: 78 | D36: 61 | E36: 47 | F36: 60 | G36: 60 | H36: 62 | I36: =AVERAGE(C36:H36) -> 61.333333 | J36: =_xlfn.RANK.EQ(I36,$I$3:$I$42,0) -> 25
A37: 3班 | B37: 2032636 | C37: 69 | D37: 62 | E37: 61 | F37: 50 | G37: 60 | H37: 60 | I37: =AVERAGE(C37:H37) -> 60.333333 | J37: =_xlfn.RANK.EQ(I37,$I$3:$I$42,0) -> 27
A38: 3班 | B38: 2032629 | C38: 55 | D38: 68 | E38: 45 | F38: 60 | G38: 60 | H38: 34 | I38: =AVERAGE(C38:H38) -> 53.666667 | J38: =_xlfn.RANK.EQ(I38,$I$3:$I$42,0) -> 31
A39: 3班 | B39: 2032637 | C39: 0 | D39: 75 | E39: 54 | F39: 51 | G39: 60 | H39: 61 | I39: =AVERAGE(C39:H39) -> 50.166667 | J39: =_xlfn.RANK.EQ(I39,$I$3:$I$42,0) -> 33
A40: 3班 | B40: 2032635 | C40: 0 | D40: 55 | E40: 55 | F40: 60 | G40: 60 | H40: 60 | I40: =AVERAGE(C40:H40) -> 48.333333 | J40: =_xlfn.RANK.EQ(I40,$I$3:$I$42,0) -> 34
A41: 3班 | B41: 2032630 | C41: 47 | D41: 63 | E41: 40 | F41: 48 | G41: 60 | H41: 7 | I41: =AVERAGE(C41:H41) -> 44.166667 | J41: =_xlfn.RANK.EQ(I41,$I$3:$I$42,0) -> 37
A42: 3班 | B42: 2032631 | C42: 38 | D42: 70 | E42: 28 | F42: 47 | G42: 60 | H42: 22 | I42: =AVERAGE(C42:H42) -> 44.166667 | J42: =_xlfn.RANK.EQ(I42,$I$3:$I$42,0) -> 37
...
